Workbook

Sheet Portada
B2: Bolivia: ¿otro programa de estabilización es posible?
B3: Simulación contrafactual del Acuerdo SAF/EFF del FMI (36 meses, 2026–2029) · Maestría GPP · Macroeconomía para el Desarrollo
B5: Pregunta central | C5: ¿Se puede alcanzar la estabilidad que persigue el FMI con otra combinación de políticas fiscal, monetaria, cambiaria y tributaria, con menor costo social o recuperación productiva más rápida?
B6: Fuente principal | C6: FMI, Bolivia: Solicitud de un Acuerdo Ampliado en virtud del SAF (Informe del personal, 22-sep-2026; aprobación del Directorio 2-oct-2026, PR26/317). Versión traducida automáticamente; cifras leídas de Tablas 1, 2a, 2b, 4a, 4b, 5, 6 y Tablas de texto 1–3.
B7: Metas de prueba | C7: Criterios cuantitativos e indicativos a dic-2026 según la consigna (saldo primario, RIN, crédito BCB, asistencia social, base monetaria).
B8: Cómo usarlo | C8: 1) Elija escenario, shock, año del shock y respuesta en el Dashboard (celdas amarillas). 2) Ajuste las palancas de cada escenario en 'Palancas' (texto azul). 3) Ajuste parámetros en 'Supuestos'. Todo se recalcula con fórmulas.
B9: Escenarios | C9: Base FMI · E1 Fiscal gradual · E2 Monetaria con crédito productivo · E3 Banda cambiaria · E4 Tributaria progresiva · E5 Protección social y subsidio gradual · E6 Programa alternativo integrado (combinación eficiente).
B10: Naturaleza del modelo | C10: Modelo semiestructural de desviaciones respecto de la senda FMI: cada escenario = proyección FMI + efecto de las palancas vía multiplicadores, traspasos y elasticidades documentados. No es econométrico; es una herramienta de coherencia contable y de canales de transmisión para la defensa oral.
B11: Convención de colores | C11: Texto azul = dato de entrada/palanca editable · Negro = fórmula · Verde = vínculo a otra hoja · Fondo amarillo = selector o supuesto clave.
B12: Advertencia | C12: Las proyecciones alternativas son ejercicios contrafactuales del equipo, no pronósticos oficiales. Los shocks son hipotéticos (consigna, misión 5).
B14: Hojas
B15: Dashboard | C15: Selectores, semáforo de metas, indicadores clave, comparación de escenarios y gráficos.
B16: Datos_FMI | C16: Senda base del programa 2024–2031 transcrita del informe, con fuente por fila.
B17: Metas | C17: Las cinco metas de prueba a dic-2026.
B18: Supuestos | C18: Parámetros del modelo (multiplicadores, traspasos, elasticidades) con justificación.
B19: Palancas | C19: Decisiones de política por escenario y año (entradas).
B20: Motor | C20: Cálculo por escenario: fiscal, financiamiento, crecimiento, inflación, deuda, reservas, crédito, empleo y distribución.
B21: Shocks | C21: Cisne negro boliviano: impacto de cada shock sobre el escenario elegido, con respuesta de política.
B22: Seleccionado | C22: Escenario elegido + shock, frente a la Base FMI (alimenta el Dashboard).
B23: Evaluacion | C23: Cumplimiento de metas y índice de eficiencia de todos los escenarios.
B24: Contrafactual | C24: Presupuesto contrafactual de la consigna: FMI vs alternativo con justificación.
B25: Matriz_Instrumentos | C25: Qué instrumento cambia, cómo funciona, quién gana/pierde, costo, financiamiento y riesgo.
B26: Diagnostico | C26: Auditoría del diagnóstico del FMI (misión 1).
... B28: Negociacion | C28: Condicionalidad alternativa: metas verificables, calendario y seguimiento (misión 6).

Sheet Dashboard
B2: Bolivia 2026–2029 · Programa FMI vs programa alternativo
B3: Simulación contrafactual con metas de prueba a dic-2026, shocks 'cisne negro' y evaluación de eficiencia. Cifras en Bs mn / US$ mn / % según fila.
B5: Escenario a evaluar | C5: E6 Alternativo integrado | G5: Descripción del escenario
B6: Shock (cisne negro) | C6: Ninguno | G6: =INDEX(Listas!$C$2:$C$8,MATCH(sel_scen,Listas!$B$2:$B$8,0)) -> Combinación eficiente: 2026 intacto para cumplir metas; desde 2027 inversión productiva + reforma tributaria progresiva/antievasión + recorte de gasto corriente y reestructuración de EP + crédito productivo neutral en base monetaria + flotación administrada con reglas + red social reforzada.
B7: Año del shock | C7: 2027
B8: ¿Activar respuesta de política? | C8: Sí
B10: Metas de prueba a dic-2026 · escenario seleccionado + shock | C10: Valor | D10: Meta | E10: Holgura | F10: Estado | H10: Indicador | J10: FMI 2026 | K10: FMI 2027 | L10: FMI 2028 | M10: FMI 2029 | N10: Alt. 2026 | O10: Alt. 2027 | P10: Alt. 2028 | Q10: Alt. 2029
B11: =Seleccionado!B25 -> Saldo primario (Bs mn) | C11: =Seleccionado!C25 -> -32751.77 | D11: =Seleccionado!D25 -> -33000 | E11: =Seleccionado!E25 -> 248.22952 | F11: =Seleccionado!F25 -> Cumple | H11: =Seleccionado!B7 -> Crecimiento PIB real (%) | J11: =Seleccionado!C7 -> -3 | K11: =Seleccionado!D7 -> -1.5 | L11: =Seleccionado!E7 -> 0.5 | M11: =Seleccionado!F7 -> 2.5 | N11: =Seleccionado!G7 -> -2.97175 | O11: =Seleccionado!H7 -> -0.808 | P11: =Seleccionado!I7 -> 1.059 | Q11: =Seleccionado!J7 -> 2.861
B12: =Seleccionado!B26 -> Variación RIN (US$ mn) | C12: =Seleccionado!C26 -> 2403.7065 | D12: =Seleccionado!D26 -> 2400 | E12: =Seleccionado!E26 -> 3.706515 | F12: =Seleccionado!F26 -> Cumple | H12: =Seleccionado!B8 -> Inflación promedio (%) | J12: =Seleccionado!C8 -> 12.7 | K12: =Seleccionado!D8 -> 15.8 | L12: =Seleccionado!E8 -> 8.2 | M12: =Seleccionado!F8 -> 7.3 | N12: =Seleccionado!G8 -> 12.710562 | O12: =Seleccionado!H8 -> 15.8265 | P12: =Seleccionado!I8 -> 8.31375 | Q12: =Seleccionado!J8 -> 7.32725
B13: =Seleccionado!B27 -> Crédito BCB al sector público (Bs mn) | C13: =Seleccionado!C27 -> 0 | D13: =Seleccionado!D27 -> 0 | E13: =Seleccionado!E27 -> 0 | F13: =Seleccionado!F27 -> Cumple | H13: =Seleccionado!B10 -> Saldo primario (% PIB) | J13: =Seleccionado!C10 -> -6.5 | K13: =Seleccionado!D10 -> -3 | L13: =Seleccionado!E10 -> -0.3 | M13: =Seleccionado!F10 -> 0.6 | N13: =Seleccionado!G10 -> -6.47685 | O13: =Seleccionado!H10 -> -2.8866 | P13: =Seleccionado!I10 -> 0.4518 | Q13: =Seleccionado!J10 -> 1.6622
B14: =Seleccionado!B28 -> Asistencia social (Bs mn) | C14: =Seleccionado!C28 -> 10890 | D14: =Seleccionado!D28 -> 9300 | E14: =Seleccionado!E28 -> 1590 | F14: =Seleccionado!F28 -> Cumple | H14: =Seleccionado!B13 -> Deuda SPNF (% PIB) | J14: =Seleccionado!C13 -> 100.47769 | K14: =Seleccionado!D13 -> 95.361223 | L14: =Seleccionado!E13 -> 93.185529 | M14: =Seleccionado!F13 -> 89.203374 | N14: =Seleccionado!G13 -> 100.41557 | O14: =Seleccionado!H13 -> 94.214638 | P14: =Seleccionado!I13 -> 90.314434 | Q14: =Seleccionado!J13 -> 84.846923
B15: =Seleccionado!B29 -> Base monetaria (Bs mn) | C15: =Seleccionado!C29 -> 133900 | D15: =Seleccionado!D29 -> 133900 | E15: =Seleccionado!E29 -> 0 | F15: =Seleccionado!F29 -> Cumple | H15: =Seleccionado!B14 -> RIN del programa (US$ mn) | J15: =Seleccionado!C14 -> -581 | K15: =Seleccionado!D14 -> 744 | L15: =Seleccionado!E14 -> 1304 | M15: =Seleccionado!F14 -> 1878 | N15: =Seleccionado!G14 -> -586.29349 | O15: =Seleccionado!H14 -> 703.74912 | P15: =Seleccionado!I14 -> 1302.8827 | Q15: =Seleccionado!J14 -> 1800.8561
B16: Metas cumplidas | C16: =COUNTIF(F11:F15,"Cumple")&" de 5" -> 5 de 5 | H16: =Seleccionado!B16 -> Crédito privado (variación %) | J16: =Seleccionado!C16 -> 4 | K16: =Seleccionado!D16 -> 7.3 | L16: =Seleccionado!E16 -> 7.3 | M16: =Seleccionado!F16 -> 9.5 | N16: =Seleccionado!G16 -> 4.25 | O16: =Seleccionado!H16 -> 10.55 | P16: =Seleccionado!I16 -> 10.3 | Q16: =Seleccionado!J16 -> 11.5
H17: =Seleccionado!B19 -> Asistencia social (Bs mn) | J17: =Seleccionado!C19 -> 10890 | K17: =Seleccionado!D19 -> 12722.578 | L17: =Seleccionado!E19 -> 8064.823 | M17: =Seleccionado!F19 -> 8813.142 | N17: =Seleccionado!G19 -> 10890 | O17: =Seleccionado!H19 -> 14168.326 | P17: =Seleccionado!I19 -> 9305.565 | Q17: =Seleccionado!J19 -> 9830.043
H18: =Seleccionado!B20 -> Δ Empleo vs FMI (miles) | J18: =Seleccionado!C20 -> 0 | K18: =Seleccionado!D20 -> 0 | L18: =Seleccionado!E20 -> 0 | M18: =Seleccionado!F20 -> 0 | N18: =Seleccionado!G20 -> 0.904 | O18: =Seleccionado!H20 -> 23.048 | P18: =Seleccionado!I20 -> 40.936 | Q18: =Seleccionado!J20 -> 52.488
H19: =Seleccionado!B21 -> Δ Pobreza vs FMI (pp) | J19: =Seleccionado!C21 -> 0 | K19: =Seleccionado!D21 -> 0 | L19: =Seleccionado!E21 -> 0 | M19: =Seleccionado!F21 -> 0 | N19: =Seleccionado!G21 -> -0.018190625 | O19: =Seleccionado!H21 -> -1.0602 | P19: =Seleccionado!I21 -> -1.2784125 | Q19: =Seleccionado!J21 -> -1.4440875
B22: Comparación de escenarios (sin shock) | C22: Base FMI | D22: E1 Fiscal gradual | E22: E2 Monetaria-crédito | F22: E3 Banda cambiaria | G22: E4 Tributaria progresiva | H22: E5 Protección social | I22: E6 Alternativo integrado
B23: Metas 2026 cumplidas (de 5) | C23: =Evaluacion!C16 -> 5 | D23: =Evaluacion!D16 -> 4 | E23: =Evaluacion!E16 -> 5 | F23: =Evaluacion!F16 -> 4 | G23: =Evaluacion!G16 -> 5 | H23: =Evaluacion!H16 -> 5 | I23: =Evaluacion!I16 -> 5
B24: Meta saldo primario | C24: =Evaluacion!C11 -> Cumple | D24: =Evaluacion!D11 -> No cumple | E24: =Evaluacion!E11 -> Cumple | F24: =Evaluacion!F11 -> Cumple | G24: =Evaluacion!G11 -> Cumple | H24: =Evaluacion!H11 -> Cumple | I24: =Evaluacion!I11 -> Cumple
B25: Meta RIN | C25: =Evaluacion!C12 -> Cumple | D25: =Evaluacion!D12 -> Cumple | E25: =Evaluacion!E12 -> Cumple | F25: =Evaluacion!F12 -> No cumple | G25: =Evaluacion!G12 -> Cumple | H25: =Evaluacion!H12 -> Cumple | I25: =Evaluacion!I12 -> Cumple
B26: Meta crédito BCB | C26: =Evaluacion!C13 -> Cumple | D26: =Evaluacion!D13 -> Cumple | E26: =Evaluacion!E13 -> Cumple | F26: =Evaluacion!F13 -> Cumple | G26: =Evaluacion!G13 -> Cumple | H26: =Evaluacion!H13 -> Cumple | I26: =Evaluacion!I13 -> Cumple
B27: Meta asistencia social | C27: =Evaluacion!C14 -> Cumple | D27: =Evaluacion!D14 -> Cumple | E27: =Evaluacion!E14 -> Cumple | F27: =Evaluacion!F14 -> Cumple | G27: =Evaluacion!G14 -> Cumple | H27: =Evaluacion!H14 -> Cumple | I27: =Evaluacion!I14 -> Cumple
B28: Meta base monetaria | C28: =Evaluacion!C15 -> Cumple | D28: =Evaluacion!D15 -> Cumple | E28: =Evaluacion!E15 -> Cumple | F28: =Evaluacion!F15 -> Cumple | G28: =Evaluacion!G15 -> Cumple | H28: =Evaluacion!H15 -> Cumple | I28: =Evaluacion!I15 -> Cumple
B29: Crecimiento acumulado 2026–29 (%) | C29: =Evaluacion!C18 -> -1.5767069 | D29: =Evaluacion!D18 -> 0.17629456 | E29: =Evaluacion!E18 -> -0.065671377 | F29: =Evaluacion!F18 -> -1.8013202 | G29: =Evaluacion!G18 -> -2.2080605 | H29: =Evaluacion!H18 -> -1.3167587 | I29: =Evaluacion!I18 -> 0.046196877
B30: Inflación promedio 2026–29 (%) | C30: =Evaluacion!C19 -> 11 | D30: =Evaluacion!D19 -> 11.110938 | E30: =Evaluacion!E19 -> 11.676875 | F30: =Evaluacion!F19 -> 10.329555 | G30: =Evaluacion!G19 -> 11.041781 | H30: =Evaluacion!H19 -> 11.016394 | I30: =Evaluacion!I19 -> 11.044516
B31: Deuda 2029 (% PIB) | C31: =Evaluacion!C21 -> 89.203374 | D31: =Evaluacion!D21 -> 89.229857 | E31: =Evaluacion!E21 -> 85.830045 | F31: =Evaluacion!F21 -> 88.799442 | G31: =Evaluacion!G21 -> 86.134624 | H31: =Evaluacion!H21 -> 89.923874 | I31: =Evaluacion!I21 -> 84.846923
B32: RIN 2029 (US$ mn) | C32: =Evaluacion!C22 -> 1878 | D32: =Evaluacion!D22 -> 2727.2943 | E32: =Evaluacion!E22 -> 1397.2205 | F32: =Evaluacion!F22 -> 771.74304 | G32: =Evaluacion!G22 -> 2007.4171 | H32: =Evaluacion!H22 -> 1980.4677 | I32: =Evaluacion!I22 -> 1800.8561
B33: Δ Pobreza 2029 (pp) | C33: =Evaluacion!C27 -> 0 | D33: =Evaluacion!D27 -> -1.2221563 | E33: =Evaluacion!E27 -> -0.99825 | F33: =Evaluacion!F27 -> 0.10535516 | G33: =Evaluacion!G27 -> 0.46481875 | H33: =Evaluacion!H27 -> -0.52869348 | I33: =Evaluacion!I27 -> -1.4440875
B34: Δ Empleo 2029 (miles) | C34: =Evaluacion!C26 -> 0 | D34: =Evaluacion!D26 -> 56.8 | E34: =Evaluacion!E26 -> 48.96 | F34: =Evaluacion!F26 -> -7.2676645 | G34: =Evaluacion!G26 -> -20.72 | H34: =Evaluacion!H26 -> 8.3937691 | I34: =Evaluacion!I26 -> 52.488
B35: Crédito BCB 2026–29 (Bs mn) | C35: =Evaluacion!C17 -> 0 | D35: =Evaluacion!D17 -> 0 | E35: =Evaluacion!E17 -> 0 | F35: =Evaluacion!F17 -> 0 | G35: =Evaluacion!G17 -> 0 | H35: =Evaluacion!H17 -> 0 | I35: =Evaluacion!I17 -> 0
B36: Índice de eficiencia (0–100) | C36: =Evaluacion!C38 -> 49.388775 | D36: =Evaluacion!D38 -> 52.18859 | E36: =Evaluacion!E38 -> 70.422955 | F36: =Evaluacion!F38 -> 24.484664 | G36: =Evaluacion!G38 -> 49.584885 | H36: =Evaluacion!H38 -> 53.092957 | I36: =Evaluacion!I38 -> 85.933332
B37: Ranking | C37: =Evaluacion!C39 -> 6 | D37: =Evaluacion!D39 -> 4 | E37: =Evaluacion!E39 -> 2 | F37: =Evaluacion!F39 -> 7 | G37: =Evaluacion!G39 -> 5 | H37: =Evaluacion!H39 -> 3 | I37: =Evaluacion!I39 -> 1
C38: Base FMI | D38: E1 Fiscal gradual | E38: E2 Monetaria-crédito | F38: E3 Banda cambiaria | G38: E4 Tributaria progresiva | H38: E5 Protección social | I38: E6 Alternativo integrado
B39: Saldo primario 2026 (Bs mn) | C39: =Evaluacion!C6 -> -32869 | D39: =Evaluacion!D6 -> -33413.37 | E39: =Evaluacion!E6 -> -32838.617 | F39: =Evaluacion!F6 -> -32884.192 | G39: =Evaluacion!G6 -> -32695.308 | H39: =Evaluacion!H6 -> -32858.872 | I39: =Evaluacion!I6 -> -32751.77
B40: Meta saldo primario 2026 | C40: =meta_pb -> -33000 | D40: =meta_pb -> -33000 | E40: =meta_pb -> -33000 | F40: =meta_pb -> -33000 | G40: =meta_pb -> -33000 | H40: =meta_pb -> -33000 | I40: =meta_pb -> -33000
B41: Variación RIN 2026 (US$ mn) | C41: =Evaluacion!C7 -> 2409 | D41: =Evaluacion!D7 -> 2492.6042 | E41: =Evaluacion!E7 -> 2403.3786 | F41: =Evaluacion!F7 -> 2261.8107 | G41: =Evaluacion!G7 -> 2409.6558 | H41: =Evaluacion!H7 -> 2407.1262 | I41: =Evaluacion!I7 -> 2403.7065
B42: Meta RIN 2026 | C42: =meta_nir -> 2400 | D42: =meta_nir -> 2400 | E42: =meta_nir -> 2400 | F42: =meta_nir -> 2400 | G42: =meta_nir -> 2400 | H42: =meta_nir -> 2400 | I42: =meta_nir -> 2400
B44: Años (categorías de gráficos) | C44: 2026 | D44: 2027 | E44: 2028 | F44: 2029
B46: Gráficos: escenario seleccionado (+shock) vs Base FMI
B77: Gráficos: comparación de los 7 escenarios (sin shock)

Sheet Datos_FMI
B2: Senda base del programa respaldado por el FMI (2024–2031)
B3: Est. 2024–2025; proyecciones del personal técnico 2026–2031. Fuente: Informe del personal FMI, sep-2026 (traducción automática).
B5: Indicador | C5: Unidad | D5: 2024 | E5: 2025 | F5: 2026 | G5: 2027 | H5: 2028 | I5: 2029 | J5: 2030 | K5: 2031 | L5: Fuente (informe FMI)
B6: PIB real (variación) | C6: % | D6: -1.1 | E6: -1.6 | F6: -3 | G6: -1.5 | H6: 0.5 | I6: 2.5 | J6: 2.9 | K6: 2.7 | L6: Tabla 1, p.41
B7: Inflación IPC (promedio del período) | C7: % | D7: 5.1 | E7: 19.5 | F7: 12.7 | G7: 15.8 | H7: 8.2 | I7: 7.3 | J7: 5.8 | K7: 5 | L7: Tabla 1, p.41
B8: Inflación IPC (fin de período) | C8: % | D8: 10 | E8: 20.4 | F8: 14.2 | G8: 10.7 | H8: 8.7 | I8: 6.2 | J8: 5.5 | K8: 5 | L8: Tabla 1, p.41
B9: PIB nominal | C9: Bs mn | D9: 379230 | E9: 447553 | F9: 506391 | G9: 578299 | H9: 620371 | I9: 677934 | J9: 733289 | K9: 786849 | L9: Tabla 2a, p.42
B10: Ingresos y donaciones SPNF | C10: % PIB | D10: 23 | E10: 16.8 | F10: 16.9 | G10: 17.3 | H10: 19.1 | I10: 20 | J10: 20.8 | K10: 20.9 | L10: Tabla 2b, p.43
B11: Gasto total SPNF | C11: % PIB | D11: 31.7 | E11: 28.2 | F11: 26.1 | G11: 24 | H11: 23 | I11: 23.2 | J11: 23.2 | K11: 23.1 | L11: Tabla 2b, p.43
B12: Inversión pública (adq. neta activos no financieros) | C12: % PIB | D12: 4.8 | E12: 3.5 | F12: 2.5 | G12: 2.7 | H12: 3.1 | I12: 3.3 | J12: 3.4 | K12: 3.6 | L12: Tabla 2b, p.43
B13: Prestaciones sociales (asistencia social, def. MTE) | C13: % PIB | D13: 1.6 | E13: 1.2 | F13: 2.2 | G13: 2.2 | H13: 1.3 | I13: 1.3 | J13: 1.3 | K13: 1.3 | L13: Tabla 2b, p.43
B14: Prestaciones sociales | C14: Bs mn | D14: 6069 | E14: 5525 | F14: 10890 | G14: =G13/100*G9 -> 12722.578 | H14: =H13/100*H9 -> 8064.823 | I14: =I13/100*I9 -> 8813.142 | J14: =J13/100*J9 -> 9532.757 | K14: =K13/100*K9 -> 10229.037 | L14: Tabla 2a, p.42
B15: Subsidios energéticos a empresas estatales | C15: % PIB | D15: 3.5 | E15: 3.3 | F15: 2.9 | G15: 0 | H15: 0 | I15: 0 | J15: 0 | K15: 0 | L15: Tabla 1 / Tabla 2b
B16: Intereses | C16: % PIB | D16: 2.6 | E16: 2.5 | F16: 2.7 | G16: 3.7 | H16: 3.7 | I16: 3.8 | J16: 3.7 | K16: 3.6 | L16: Tabla 2b, p.43
B17: Saldo primario SPNF | C17: % PIB | D17: -6.1 | E17: -8.8 | F17: -6.5 | G17: -3 | H17: -0.3 | I17: 0.6 | J17: 1.3 | K17: 1.4 | L17: Tabla 1 / 2b
B18: Saldo primario SPNF | C18: Bs mn | D18: -22971 | E18: -39587 | F18: -32869 | G18: -17466 | H18: =H17/100*H9 -> -1861.113 | I18: =I17/100*I9 -> 4067.604 | J18: =J17/100*J9 -> 9532.757 | K18: =K17/100*K9 -> 11015.886 | L18: Tabla 2a, p.42 (2028+ = %×PIB)
B19: Saldo global SPNF | C19: % PIB | D19: -8.7 | E19: -11.4 | F19: -9.2 | G19: -6.7 | H19: -4 | I19: -3.2 | J19: -2.4 | K19: -2.2 | L19: Tabla 1 / 2b
B20: Deuda bruta total SPNF | C20: % PIB | D20: 83.2 | E20: 83.3 | F20: 100.5 | G20: 95.4 | H20: 93.2 | I20: 89.2 | J20: 85.7 | K20: 82.7 | L20: Tabla 1 / 2b
B21: Deuda bruta total SPNF | C21: Bs mn | D21: 315590 | E21: 372887 | F21: 508810 | G21: 551473 | H21: 578096 | I21: 604740 | J21: 628114 | K21: 650725 | L21: Tabla 2a, p.42
B22: de la cual: deuda externa | C22: Bs mn | D22: 91550 | E22: 98284 | F22: 204596 | G22: 229658 | H22: 238910 | I22: 249488 | J22: 259994 | K22: 269237 | L22: Tabla 2a, p.42
B23: Cuenta corriente | C23: % PIB | D23: -2.4 | E23: -1.9 | F23: 1.6 | G23: 1 | H23: 0.4 | I23: -0.3 | J23: -1 | K23: -1.6 | L23: Tabla 1 / 4b
B24: Importaciones de bienes y servicios | C24: US$ mn | D24: n.d. | E24: n.d. | F24: 12492 | G24: 12389 | H24: 13222 | I24: 14040 | J24: 15116 | K24: 16394 | L24: Tabla 4a, p.45
B25: Importaciones de bienes y servicios | C25: % PIB | D25: 20.6 | E25: 17.6 | F25: 23.2 | G25: 28.2 | H25: 28.5 | I25: 28.1 | J25: 28.4 | K25: 29.1 | L25: Tabla 4b, p.46
B26: Importación de combustibles y lubricantes | C26: US$ mn | D26: n.d. | E26: n.d. | F26: 3845 | G26: 3215 | H26: 3107 | I26: 3126 | J26: 3152 | K26: 3175 | L26: Tabla 4a, p.45
B27: Reservas internacionales brutas (total BCB) | C27: US$ mn | D27: 1977 | E27: 3713 | F27: 5734 | G27: 7297 | H27: 8100 | I27: 8937 | J27: 9258 | K27: 9644 | L27: Tabla 1, p.41
B28: RIB del programa (netas de oro gravado) | C28: US$ mn | D28: 132 | E28: 627 | F28: 2458 | G28: 3982 | H28: 4690 | I28: 5527 | J28: 5847 | K28: 6234 | L28: Tabla 1, p.41
B29: RIB programa en % de la métrica ARA (flotante) | C29: % | D29: 2.7 | E29: 10.9 | F29: 53.4 | G29: 86.1 | H29: 100.1 | I29: 112.3 | J29: 114 | K29: 120.2 | L29: Tabla 1, p.41
B30: RIB programa en meses de importaciones | C30: meses | D30: 0.1 | E30: 0.6 | F30: 2.4 | G30: 3.6 | H30: 4 | I30: 4.4 | J30: 4.3 | K30: 4.3 | L30: Tabla 1, p.41
B31: Reservas internacionales netas del programa (stock) | C31: US$ mn | D31: n.d. | E31: -2990 | F31: -581 | G31: 744 | H31: 1304 | I31: 1878 | J31: 2199 | K31: 2676 | L31: Tabla 4a/4b, memo (p.45–46)
B32: Crédito al sector privado (variación) | C32: % | D32: 3.2 | E32: 3.1 | F32: 4 | G32: 7.3 | H32: 7.3 | I32: 9.5 | J32: 8.7 | K32: 8.4 | L32: Tabla 1 / Tabla 6
B33: Crédito bancario al sector privado | C33: % PIB | D33: 59.2 | E33: 51.7 | F33: 47.6 | G33: 44.7 | H33: 44.7 | I33: 44.8 | J33: 45 | K33: 45.5 | L33: Tabla 6, p.48
B34: Base monetaria (definición del programa) | C34: Bs mn | D34: 104819 | E34: 132269 | F34: 136564 | G34: 148333 | H34: 161304 | I34: 177013 | J34: 192144 | K34: 206603 | L34: Tabla 6, p.48
B35: Precio del petróleo (APSP) | C35: US$/barril | D35: 79.2 | E35: 67.7 | F35: 89.3 | G35: 78.7 | H35: 74.2 | I35: 71.5 | J35: 69.4 | K35: 67.6 | L35: Tabla de texto 2, p.14
B36: Financiamiento oficial neto IFI (excl. FMI) | C36: US$ mn | D36: n.d. | E36: n.d. | F36: 1500 | G36: 1800 | H36: 800 | I36: 0 | J36: n.d. | K36: n.d. | L36: Tabla de texto 3, p.27
B37: Desembolsos FMI (proyección) | C37: US$ mn | D37: n.d. | E37: n.d. | F37: 400 | G37: 700 | H37: 500 | I37: 300 | J37: n.d. | K37: n.d. | L37: Tabla de texto 3, p.27
B38: Nuevo financiamiento de mercado | C38: US$ mn | D38: n.d. | E38: n.d. | F38: 1000 | G38: 0 | H38: 0 | I38: 600 | J38: n.d. | K38: n.d. | L38: Tabla de texto 3, p.27
B40: Derivados (cálculo propio a partir del informe)
B41: PIB nominal en US$ (implícito = importaciones US$ ÷ % PIB) | C41: US$ mn | F41: =F24/(F25/100) -> 53844.828 | G41: =G24/(G25/100) -> 43932.624 | H41: =H24/(H25/100) -> 46392.982 | I41: =I24/(I25/100) -> 49964.413 | J41: =J24/(J25/100) -> 53225.352 | K41: =K24/(K25/100) -> 56336.77 | L41: Derivado: Tabla 4a ÷ Tabla 4b
B42: Tipo de cambio promedio implícito | C42: Bs/US$ | F42: =F9/F41 -> 9.4046359 | G42: =G9/G41 -> 13.163316 | H42: =H9/H41 -> 13.372087 | I42: =I9/I41 -> 13.568337 | J42: =J9/J41 -> 13.777062 | K42: =K9/K41 -> 13.966882 | L42: Derivado: PIB Bs ÷ PIB US$ (el informe cita Bs 12,8 de mercado en 2025)
B43: Variación de RIN del programa (meta: acumulada en el año) | C43: US$ mn | F43: =F31-E31 -> 2409 | G43: =G31-F31 -> 1325 | H43: =H31-G31 -> 560 | I43: =I31-H31 -> 574 | J43: =J31-I31 -> 321 | K43: =K31-J31 -> 477 | L43: 2026: +2.409 ≈ meta de +2.400 (consistencia)
...

Sheet Metas
B2: Metas de prueba del programa a diciembre de 2026
B3: Fuente: consigna (tabla de criterios cuantitativos y metas indicativas del informe FMI). Valores de prueba, no resultados observados.
B5: Indicador del programa | C5: Tipo | D5: Meta | E5: Unidad | F5: Cómo se mide en el modelo
B6: Saldo primario acumulado del SPNF (piso) | C6: Criterio de desempeño | D6: -33000 | E6: Bs mn | F6: Saldo primario 2026 del escenario (Tabla 2a: base −32.869) + cambio discrecional y automático
B7: Variación acumulada de RIN del programa (piso) | C7: Criterio de desempeño | D7: 2400 | E7: US$ mn | F7: RIN programa 2026 − RIN 2025 (−2.990); base +2.409
B8: Nuevos créditos brutos del BCB al sector público (techo) | C8: Criterio continuo | D8: 0 | E8: Bs mn | F8: Brecha de financiamiento no cubierta por fuentes externas ni mercado interno
B9: Gasto acumulado en asistencia social (piso) | C9: Meta indicativa | D9: 9300 | E9: Bs mn | F9: Prestaciones sociales 2026 (Tabla 2a: 10.890) + asistencia adicional
B10: Base monetaria (techo) | C10: Meta indicativa | D10: 133900 | E10: Bs mn | F10: Supuesto: la senda base se calibra en la meta; + expansión del escenario + monetización
B12: Holgura de la senda base FMI frente a cada meta
B13: Saldo primario: −32.869 vs −33.000 → holgura de solo Bs 131 mn (0,03% del PIB). 2026 está prácticamente cerrado: cualquier gasto nuevo en el 4º trimestre rompe la meta.
B14: RIN: +2.409 vs +2.400 → holgura de US$ 9 mn. Cualquier intervención cambiaria en 2026 incumple el piso.

Sheet Supuestos
B2: Supuestos y parámetros del modelo (editables)
B3: Texto azul con fondo amarillo = parámetro. Rangos de literatura como referencia; calibración del equipo para fines docentes.
B5: Nombre | C5: Parámetro | D5: Valor | E5: Unidad | F5: Justificación / canal de transmisión
B6: Calendario
B7: ef26 | C7: Fracción de 2026 en que pueden operar medidas nuevas | D7: 0.25 | E7: fracción | F7: El informe es de sep-2026 y el Directorio aprobó el 2-oct-2026: solo queda el 4º trimestre. Se aplica a palancas en pp del PIB en 2026.
B8: Multiplicadores fiscales (efecto en pp del PIB real por 1 pp del PIB)
B9: m_inv | C9: Inversión pública productiva | D9: 0.7 | E9: x | F9: Ilzetzki-Mendoza-Végh (2013): multiplicadores de inversión mayores que los de consumo en países en desarrollo; contenido importado alto en Bolivia limita el valor.
B10: m_cur | C10: Gasto corriente (salarios, bienes y servicios, transferencias a EP) | D10: 0.4 | E10: x | F10: Economía con tipo de cambio más flexible y alta informalidad: multiplicador de consumo público moderado.
B11: m_sub | C11: Subsidio a combustibles | D11: 0.2 | E11: x | F11: Bajo: parte se filtra a contrabando e importaciones y beneficia a quintiles altos.
B12: m_soc | C12: Transferencias sociales focalizadas | D12: 0.6 | E12: x | F12: Alta propensión a consumir de hogares pobres (bonos Juancito Pinto, Juana Azurduy, PEPE).
B13: m_tev | C13: Recaudación por menor evasión / administración | D13: 0.1 | E13: x | F13: Recae sobre quien ya debía pagar; bajo efecto contractivo.
B14: m_tpr | C14: Recaudación por progresividad (renta personal, patrimonio, rentas financieras) | D14: 0.15 | E14: x | F14: Afecta a deciles altos con menor propensión marginal a consumir.
B15: m_tex | C15: Recaudación por revisión de exenciones | D15: 0.3 | E15: x | F15: Revertir exenciones de 2025–26 encarece importaciones e insumos de sectores beneficiados.
B16: Rendimiento real de la reforma tributaria (realización)
B17: r_tev | C17: Realización de medidas anti-evasión | D17: 0.7 | E17: fracción | F17: Facturación electrónica y fiscalización del SIN maduran con rezago; no se recauda el 100% del potencial.
B18: r_tpr | C18: Realización de medidas de progresividad | D18: 0.6 | E18: fracción | F18: Requiere ley; base estrecha, elusión y planificación fiscal.
B19: r_tex | C19: Realización de revisión de exenciones | D19: 0.85 | E19: fracción | F19: Medida administrativa/decreto de alta realización.
B20: Canales de crecimiento
B21: s_inv | C21: Efecto oferta de la inversión acumulada (pp de crecimiento por pp PIB invertido el año previo) | D21: 0.1 | E21: x | F21: Infraestructura productiva eleva el producto potencial con rezago (PIMA para filtrar proyectos).
B22: eps_cred | C22: Elasticidad del PIB al crecimiento del crédito privado | D22: 0.12 | E22: pp/pp | F22: Crédito/PIB ≈ 45% (Tabla 6): 1 pp más de crédito ≈ 0,45% del PIB de financiamiento, con impulso parcial a inversión.
B23: kappa | C23: Penalización de credibilidad por relajamiento fiscal (pp PIB por pp de déficit sobre la tolerancia) | D23: 0.3 | E23: x | F23: Mayor riesgo soberano (calificación CCC) eleva spreads y deprime inversión privada.
B24: tol | C24: Tolerancia de relajamiento sin costo de credibilidad | D24: 0.5 | E24: pp PIB | F24: Desvíos pequeños y anunciados con financiamiento identificado no alteran expectativas.
B25: nu_dep | C25: Efecto de la depreciación real sobre exportaciones netas | D25: 0.03 | E25: pp/pp | F25: Moderado: exportaciones dominadas por minerales y soya con precios internacionales.
B26: auto | C26: Estabilizador automático (mejora del saldo primario por pp de crecimiento) | D26: 0.2 | E26: pp/pp | F26: Gasto rígido en términos nominales e ingresos con elasticidad ≈1 al PIB.
B27: Canales de inflación
B28: phi_sub | C28: Traspaso de cambios en el subsidio a la inflación (pp por pp PIB de subsidio) | D28: 1.2 | E28: pp/pp | F28: Gasolina +86% y diésel +160% en dic-2025 (Recuadro 1) se reflejaron en transporte y alimentos.
B29: mu_bm | C29: Efecto de la expansión de la base monetaria sobre inflación | D29: 0.6 | E29: pp/pp | F29: Ancla nominal = base monetaria (párr. 22); traspaso parcial en el año.
B30: eta | C30: Presión de demanda (pp de inflación por pp de crecimiento) | D30: 0.25 | E30: pp/pp | F30: Brecha del producto negativa (3er año de recesión) limita la presión de demanda.
B31: psi | C31: Traspaso cambiario (pp de inflación por pp de depreciación) | D31: 0.35 | E31: pp/pp | F31: Economía muy abierta y dolarizada en precios de importados; rango regional 0,2–0,5.
B32: tax_pi | C32: Efecto precio del mayor cumplimiento del IVA | D32: 0.2 | E32: pp/pp | F32: Formalización del IVA traslada parte del impuesto a precios.
B33: bm_dep | C33: Depreciación adicional por pp de expansión de la base monetaria | D33: 0.5 | E33: pp/pp | F33: Exceso de liquidez en bolivianos presiona el mercado cambiario.
B34: Crédito y financiamiento
B35: bm_cred | C35: Crédito privado adicional por pp de base monetaria | D35: 0.5 | E35: pp/pp | F35: Más liquidez bancaria relaja tasas y topes.
B36: crowd | C36: Desplazamiento del crédito privado por financiamiento interno del Estado | D36: 0.5 | E36: fracción | F36: Gestora y bancos compran deuda pública en lugar de prestar al sector privado (con un año de rezago).
B37: r_int | C37: Tasa de interés efectiva sobre deuda adicional | D37: 0.065 | E37: fracción | F37: Mezcla de concesional multilateral (≈5%) y mercado interno; eurobono 2031 al 9,45%.
B38: cap_dom | C38: Capacidad del mercado interno para absorber deuda adicional | D38: 1 | E38: % PIB/año | F38: Gestora y bancos ya concentran deuda pública (párr. 26: riesgo del nexo soberano–pensiones).
B39: Sector externo
B40: imp_el | C40: Elasticidad de importaciones al PIB | D40: 1.5 | E40: x | F40: Alta dependencia de bienes de capital, insumos y combustibles importados.
B41: sub_leak | C41: Fracción del subsidio que se filtra en importaciones/contrabando | D41: 0.3 | E41: fracción | F41: Precio interno bajo vs países vecinos incentiva contrabando (DS 5676).
B42: bm_flight | C42: Pérdida de reservas por pp de expansión monetaria | D42: 60 | E42: US$ mn/pp | F42: Demanda de dólares por exceso de liquidez.
...

Sheet Palancas
B2: Palancas de política por escenario (entradas editables)
B3: Desviaciones respecto de la senda FMI. Columna 2025 = 0 (referencia). En 2026 las palancas en pp del PIB se escalan por ef26 en el Motor.
B5: 0. Base FMI
B6: Programa del EFF tal como fue aprobado: consolidación fiscal anticipada (déficit primario −6,5% → +0,6% del PIB), eliminación del subsidio a combustibles a inicios de 2027, flotación con intervención solo ante condiciones desordenadas, metas de base monetaria y cero financiamiento del BCB.
B7: Palanca | C7: 2025 | D7: 2026 | E7: 2027 | F7: 2028 | G7: 2029 | H7: Unidad
B8: Δ Inversión pública productiva | C8: 0 | D8: 0 | E8: 0 | F8: 0 | G8: 0 | H8: pp PIB
B9: Δ Gasto corriente (salarios, bienes y servicios, transferencias a EP) | C9: 0 | D9: 0 | E9: 0 | F9: 0 | G9: 0 | H9: pp PIB
B10: Δ Subsidio a combustibles vs senda FMI | C10: 0 | D10: 0 | E10: 0 | F10: 0 | G10: 0 | H10: pp PIB
B11: Δ Asistencia social focalizada | C11: 0 | D11: 0 | E11: 0 | F11: 0 | G11: 0 | H11: pp PIB
B12: Δ Recaudación potencial: anti-evasión / administración | C12: 0 | D12: 0 | E12: 0 | F12: 0 | G12: 0 | H12: pp PIB
B13: Δ Recaudación potencial: progresividad (renta, patrimonio) | C13: 0 | D13: 0 | E13: 0 | F13: 0 | G13: 0 | H13: pp PIB
B14: Δ Recaudación potencial: revisión de exenciones | C14: 0 | D14: 0 | E14: 0 | F14: 0 | G14: 0 | H14: pp PIB
B15: Δ Crecimiento de la base monetaria vs programa | C15: 0 | D15: 0 | E15: 0 | F15: 0 | G15: 0 | H15: pp
B16: Δ Crédito productivo dirigido (encaje diferenciado, garantías) | C16: 0 | D16: 0 | E16: 0 | F16: 0 | G16: 0 | H16: pp crec. crédito
B17: Δ Depreciación vs flotación (− = suavizada por banda/intervención) | C17: 0 | D17: 0 | E17: 0 | F17: 0 | G17: 0 | H17: pp
B18: Δ Financiamiento externo concesional adicional | C18: 0 | D18: 0 | E18: 0 | F18: 0 | G18: 0 | H18: US$ mn
B19: Ventas netas de divisas para sostener banda/suavizar | C19: 0 | D19: 0 | E19: 0 | F19: 0 | G19: 0 | H19: US$ mn
B20: Régimen cambiario (0 = flotación FMI · 0,5 = flotación administrada con reglas · 1 = banda) | D20: 0
B23: 1. E1 Fiscal gradual
B24: Misma meta de deuda pero con senda más lenta: se protege y amplía la inversión pública productiva (filtrada por PIMA), financiada con préstamos de proyecto de CAF/BID y mercado interno. Pregunta: ¿reducir el déficit con otra velocidad protegiendo la inversión?
B25: Palanca | C25: 2025 | D25: 2026 | E25: 2027 | F25: 2028 | G25: 2029 | H25: Unidad
B26: Δ Inversión pública productiva | C26: 0 | D26: 0.5 | E26: 1 | F26: 0.8 | G26: 0.5 | H26: pp PIB
B27: Δ Gasto corriente (salarios, bienes y servicios, transferencias a EP) | C27: 0 | D27: 0 | E27: 0 | F27: 0 | G27: 0 | H27: pp PIB
B28: Δ Subsidio a combustibles vs senda FMI | C28: 0 | D28: 0 | E28: 0 | F28: 0 | G28: 0 | H28: pp PIB
B29: Δ Asistencia social focalizada | C29: 0 | D29: 0 | E29: 0 | F29: 0 | G29: 0 | H29: pp PIB
B30: Δ Recaudación potencial: anti-evasión / administración | C30: 0 | D30: 0 | E30: 0 | F30: 0 | G30: 0 | H30: pp PIB
B31: Δ Recaudación potencial: progresividad (renta, patrimonio) | C31: 0 | D31: 0 | E31: 0 | F31: 0 | G31: 0 | H31: pp PIB
B32: Δ Recaudación potencial: revisión de exenciones | C32: 0 | D32: 0 | E32: 0 | F32: 0 | G32: 0 | H32: pp PIB
B33: Δ Crecimiento de la base monetaria vs programa | C33: 0 | D33: 0 | E33: 0 | F33: 0 | G33: 0 | H33: pp
B34: Δ Crédito productivo dirigido (encaje diferenciado, garantías) | C34: 0 | D34: 0 | E34: 0 | F34: 0 | G34: 0 | H34: pp crec. crédito
B35: Δ Depreciación vs flotación (− = suavizada por banda/intervención) | C35: 0 | D35: 0 | E35: 0 | F35: 0 | G35: 0 | H35: pp
B36: Δ Financiamiento externo concesional adicional | C36: 0 | D36: 100 | E36: 500 | F36: 400 | G36: 200 | H36: US$ mn
B37: Ventas netas de divisas para sostener banda/suavizar | C37: 0 | D37: 0 | E37: 0 | F37: 0 | G37: 0 | H37: US$ mn
B38: Régimen cambiario (0 = flotación FMI · 0,5 = flotación administrada con reglas · 1 = banda) | D38: 0
B41: 2. E2 Monetaria-crédito
B42: Se mantiene la meta de base monetaria 2026; desde 2027 expansión moderada y crédito productivo dirigido mediante encaje diferenciado y fondos de garantía (sin topes de tasas). Pregunta: ¿estabilizar precios sin restringir en exceso el crédito?
B43: Palanca | C43: 2025 | D43: 2026 | E43: 2027 | F43: 2028 | G43: 2029 | H43: Unidad
B44: Δ Inversión pública productiva | C44: 0 | D44: 0 | E44: 0 | F44: 0 | G44: 0 | H44: pp PIB
B45: Δ Gasto corriente (salarios, bienes y servicios, transferencias a EP) | C45: 0 | D45: 0 | E45: 0 | F45: 0 | G45: 0 | H45: pp PIB
B46: Δ Subsidio a combustibles vs senda FMI | C46: 0 | D46: 0 | E46: 0 | F46: 0 | G46: 0 | H46: pp PIB
...

Sheet Motor
B2: Motor de cálculo por escenario (no editar: fórmulas)
B3: Columna 2025 = condición inicial (desvíos nulos). Desvíos (Δ) respecto de la senda FMI de Datos_FMI. Bs mn salvo indicación.
B5: 0. Base FMI
B6: Variable | C6: 2025 | D6: 2026 | E6: 2027 | F6: 2028 | G6: 2029 | H6: Unidad
B7: Palancas efectivas
B8: Inversión pública productiva (efectiva) | C8: 0 | D8: =Palancas!D8*ef26 -> 0 | E8: =Palancas!E8*1 -> 0 | F8: =Palancas!F8*1 -> 0 | G8: =Palancas!G8*1 -> 0 | H8: pp PIB
B9: Gasto corriente (efectivo) | C9: 0 | D9: =Palancas!D9*ef26 -> 0 | E9: =Palancas!E9*1 -> 0 | F9: =Palancas!F9*1 -> 0 | G9: =Palancas!G9*1 -> 0 | H9: pp PIB
B10: Subsidio combustibles (efectivo) | C10: 0 | D10: =Palancas!D10*ef26 -> 0 | E10: =Palancas!E10*1 -> 0 | F10: =Palancas!F10*1 -> 0 | G10: =Palancas!G10*1 -> 0 | H10: pp PIB
B11: Asistencia social (efectiva) | C11: 0 | D11: =Palancas!D11*ef26 -> 0 | E11: =Palancas!E11*1 -> 0 | F11: =Palancas!F11*1 -> 0 | G11: =Palancas!G11*1 -> 0 | H11: pp PIB
B12: Recaudación anti-evasión realizada | C12: 0 | D12: =Palancas!D12*ef26*r_tev -> 0 | E12: =Palancas!E12*1*r_tev -> 0 | F12: =Palancas!F12*1*r_tev -> 0 | G12: =Palancas!G12*1*r_tev -> 0 | H12: pp PIB
B13: Recaudación progresiva realizada | C13: 0 | D13: =Palancas!D13*ef26*r_tpr -> 0 | E13: =Palancas!E13*1*r_tpr -> 0 | F13: =Palancas!F13*1*r_tpr -> 0 | G13: =Palancas!G13*1*r_tpr -> 0 | H13: pp PIB
B14: Recaudación por exenciones realizada | C14: 0 | D14: =Palancas!D14*ef26*r_tex -> 0 | E14: =Palancas!E14*1*r_tex -> 0 | F14: =Palancas!F14*1*r_tex -> 0 | G14: =Palancas!G14*1*r_tex -> 0 | H14: pp PIB
B15: Δ crecimiento base monetaria (efectivo) | C15: 0 | D15: =Palancas!D15*ef26 -> 0 | E15: =Palancas!E15*1 -> 0 | F15: =Palancas!F15*1 -> 0 | G15: =Palancas!G15*1 -> 0 | H15: pp
B16: Crédito productivo dirigido (efectivo) | C16: 0 | D16: =Palancas!D16*ef26 -> 0 | E16: =Palancas!E16*1 -> 0 | F16: =Palancas!F16*1 -> 0 | G16: =Palancas!G16*1 -> 0 | H16: pp
B17: Δ depreciación por palanca (efectiva) | C17: 0 | D17: =Palancas!D17*ef26 -> 0 | E17: =Palancas!E17*1 -> 0 | F17: =Palancas!F17*1 -> 0 | G17: =Palancas!G17*1 -> 0 | H17: pp
B18: Financiamiento externo adicional | C18: 0 | D18: =Palancas!D18 -> 0 | E18: =Palancas!E18 -> 0 | F18: =Palancas!F18 -> 0 | G18: =Palancas!G18 -> 0 | H18: US$ mn
B19: Intervención cambiaria (ventas) | C19: 0 | D19: =Palancas!D19 -> 0 | E19: =Palancas!E19 -> 0 | F19: =Palancas!F19 -> 0 | G19: =Palancas!G19 -> 0 | H19: US$ mn
B20: Bloque fiscal
B21: Δ Gasto primario discrecional | C21: =C8+C9+C10+C11 -> 0 | D21: =D8+D9+D10+D11 -> 0 | E21: =E8+E9+E10+E11 -> 0 | F21: =F8+F9+F10+F11 -> 0 | G21: =G8+G9+G10+G11 -> 0 | H21: pp PIB
B22: Δ Ingresos discrecionales | C22: =C12+C13+C14 -> 0 | D22: =D12+D13+D14 -> 0 | E22: =E12+E13+E14 -> 0 | F22: =F12+F13+F14 -> 0 | G22: =G12+G13+G14 -> 0 | H22: pp PIB
B23: Δ Saldo primario discrecional | C23: =C22-C21 -> 0 | D23: =D22-D21 -> 0 | E23: =E22-E21 -> 0 | F23: =F22-F21 -> 0 | G23: =G22-G21 -> 0 | H23: pp PIB
B24: Crecimiento
B25: Δ crecimiento del crédito privado | C25: 0 | D25: =D16+bm_cred*D15-crowd*C41/(Datos_FMI!$F$33/100) -> 0 | E25: =E16+bm_cred*E15-crowd*D41/(Datos_FMI!$G$33/100) -> 0 | F25: =F16+bm_cred*F15-crowd*E41/(Datos_FMI!$H$33/100) -> 0 | G25: =G16+bm_cred*G15-crowd*F41/(Datos_FMI!$I$33/100) -> 0 | H25: pp
B26: Inversión adicional acumulada | C26: 0 | D26: =C26+D8 -> 0 | E26: =D26+E8 -> 0 | F26: =E26+F8 -> 0 | G26: =F26+G8 -> 0 | H26: pp PIB
B27: Penalización de credibilidad | C27: 0 | D27: =kappa*MAX(0,-D23-tol) -> 0 | E27: =kappa*MAX(0,-E23-tol) -> 0 | F27: =kappa*MAX(0,-F23-tol) -> 0 | G27: =kappa*MAX(0,-G23-tol) -> 0 | H27: pp
B28: Δ Crecimiento PIB real | C28: 0 | D28: =m_inv*D8+m_cur*D9+m_sub*D10+m_soc*D11-(m_tev*D12+m_tpr*D13+m_tex*D14)+eps_cred*D25+s_inv*C26+nu_dep*D17-D27 -> 0 | E28: =m_inv*E8+m_cur*E9+m_sub*E10+m_soc*E11-(m_tev*E12+m_tpr*E13+m_tex*E14)+eps_cred*E25+s_inv*D26+nu_dep*E17-E27 -> 0 | F28: =m_inv*F8+m_cur*F9+m_sub*F10+m_soc*F11-(m_tev*F12+m_tpr*F13+m_tex*F14)+eps_cred*F25+s_inv*E26+nu_dep*F17-F27 -> 0 | G28: =m_inv*G8+m_cur*G9+m_sub*G10+m_soc*G11-(m_tev*G12+m_tpr*G13+m_tex*G14)+eps_cred*G25+s_inv*F26+nu_dep*G17-G27 -> 0 | H28: pp
B29: Crecimiento PIB real | C29: =Datos_FMI!$E$6+C28 -> -1.6 | D29: =Datos_FMI!$F$6+D28 -> -3 | E29: =Datos_FMI!$G$6+E28 -> -1.5 | F29: =Datos_FMI!$H$6+F28 -> 0.5 | G29: =Datos_FMI!$I$6+G28 -> 2.5 | H29: %
B30: Δ nivel PIB real acumulado | C30: 0 | D30: =C30+D28 -> 0 | E30: =D30+E28 -> 0 | F30: =E30+F28 -> 0 | G30: =F30+G28 -> 0 | H30: %
B31: Saldos fiscales y financiamiento
B32: Δ Saldo primario total (incl. estabilizador) | C32: 0 | D32: =D23+auto*D28 -> 0 | E32: =E23+auto*E28 -> 0 | F32: =F23+auto*F28 -> 0 | G32: =G23+auto*G28 -> 0 | H32: pp PIB
B33: Saldo primario | C33: =Datos_FMI!$E$17+C32 -> -8.8 | D33: =Datos_FMI!$F$17+D32 -> -6.5 | E33: =Datos_FMI!$G$17+E32 -> -3 | F33: =Datos_FMI!$H$17+F32 -> -0.3 | G33: =Datos_FMI!$I$17+G32 -> 0.6 | H33: % PIB
B34: Saldo primario | C34: =Datos_FMI!$E$18+C32/100*Datos_FMI!$E$9 -> -39587 | D34: =Datos_FMI!$F$18+D32/100*Datos_FMI!$F$9 -> -32869 | E34: =Datos_FMI!$G$18+E32/100*Datos_FMI!$G$9 -> -17466 | F34: =Datos_FMI!$H$18+F32/100*Datos_FMI!$H$9 -> -1861.113 | G34: =Datos_FMI!$I$18+G32/100*Datos_FMI!$I$9 -> 4067.604 | H34: Bs mn
B35: Δ Intereses por deuda adicional | C35: 0 | D35: =r_int*C54/Datos_FMI!$F$9*100 -> 0 | E35: =r_int*D54/Datos_FMI!$G$9*100 -> 0 | F35: =r_int*E54/Datos_FMI!$H$9*100 -> 0 | G35: =r_int*F54/Datos_FMI!$I$9*100 -> 0 | H35: pp PIB
B36: Δ Saldo global | C36: 0 | D36: =D32-D35 -> 0 | E36: =E32-E35 -> 0 | F36: =F32-F35 -> 0 | G36: =G32-G35 -> 0 | H36: pp PIB
B37: Saldo global | C37: =Datos_FMI!$E$19+C36 -> -11.4 | D37: =Datos_FMI!$F$19+D36 -> -9.2 | E37: =Datos_FMI!$G$19+E36 -> -6.7 | F37: =Datos_FMI!$H$19+F36 -> -4 | G37: =Datos_FMI!$I$19+G36 -> -3.2 | H37: % PIB
B38: Necesidad adicional de financiamiento (+) / ahorro (−) | C38: 0 | D38: =-D36/100*Datos_FMI!$F$9 -> 0 | E38: =-E36/100*Datos_FMI!$G$9 -> 0 | F38: =-F36/100*Datos_FMI!$H$9 -> 0 | G38: =-G36/100*Datos_FMI!$I$9 -> 0 | H38: Bs mn
B39: Financiamiento externo adicional | C39: 0 | D39: =D18*D46 -> 0 | E39: =E18*E46 -> 0 | F39: =F18*F46 -> 0 | G39: =G18*G46 -> 0 | H39: Bs mn
B40: Financiamiento interno de mercado (Gestora/bancos) | C40: 0 | D40: =MIN(cap_dom/100*Datos_FMI!$F$9,MAX(0,D38-D39)) -> 0 | E40: =MIN(cap_dom/100*Datos_FMI!$G$9,MAX(0,E38-E39)) -> 0 | F40: =MIN(cap_dom/100*Datos_FMI!$H$9,MAX(0,F38-F39)) -> 0 | G40: =MIN(cap_dom/100*Datos_FMI!$I$9,MAX(0,G38-G39)) -> 0 | H40: Bs mn
B41: Financiamiento interno de mercado | C41: 0 | D41: =D40/Datos_FMI!$F$9*100 -> 0 | E41: =E40/Datos_FMI!$G$9*100 -> 0 | F41: =F40/Datos_FMI!$H$9*100 -> 0 | G41: =G40/Datos_FMI!$I$9*100 -> 0 | H41: pp PIB
B42: Brecha no financiada = crédito BCB requerido | C42: 0 | D42: =MAX(0,D38-D39-D40) -> 0 | E42: =MAX(0,E38-E39-E40) -> 0 | F42: =MAX(0,F38-F39-F40) -> 0 | G42: =MAX(0,G38-G39-G40) -> 0 | H42: Bs mn
...

Sheet Shocks
B2: Quinta misión: el cisne negro boliviano (shocks hipotéticos)
B3: Impacto sobre el escenario elegido en el Dashboard. Año del shock = 100%; año siguiente = persistencia. La respuesta mitiga crecimiento e inflación a un costo fiscal.
B5: Parámetros del shock | C5: Shock petrolero (+25%) | D5: Crisis de confianza | E5: Bloqueos (3 semanas) | F5: Crisis bancaria | G5: Freno legislativo
B6: Impacto en crecimiento (pp) | C6: -0.3 | D6: -0.5 | E6: -0.6 | F6: -0.8 | G6: -0.3
B7: Impacto directo en inflación (pp) | C7: 0 | D7: 0 | E7: 1.5 | F7: 0.5 | G7: 0
B8: Impacto directo en saldo primario (pp PIB) | C8: 0 | D8: 0 | E8: -0.1 | F8: 0 | G8: 0
B9: Impacto directo en RIN (US$ mn) | C9: 0 | D9: 0 | E9: -100 | F9: -300 | G9: 0
B10: Impacto en crédito privado (pp) | C10: 0 | D10: -2 | E10: 0 | F10: -6 | G10: 0
B11: Liquidez de emergencia BCB (Bs mn, base monetaria) | C11: 0 | D11: 0 | E11: 0 | F11: 3000 | G11: 0
B12: Costo de recapitalización (pp PIB, deuda) | C12: 0 | D12: 0 | E12: 0 | F12: 0.8 | G12: 0
B13: Persistencia al año siguiente (fracción) | C13: 0.6 | D13: 0.3 | E13: 0 | F13: 0.5 | G13: 1
B14: Mitigación con respuesta (fracción de g y π evitada) | C14: 0.4 | D14: 0.4 | E14: 0.5 | F14: 0.5 | G14: 0.3
B15: Costo fiscal de la respuesta (pp PIB) | C15: 0.15 | D15: 0 | E15: 0.1 | F15: 0.2 | G15: 0
B16: Alza del precio internacional del petróleo | C16: 0.25 | D16: 0 | E16: 0 | F16: 0 | G16: 0
B17: Peso efectivo (directo+indirecto) de combustibles en IPC | C17: 0.08 | D17: 0 | E17: 0 | F17: 0 | G17: 0
... B20: Desembolsos IFI demorados un año (US$ mn) | C20: 0 | D20: 0 | E20: 0 | F20: 0 | G20: 1000
B22: Respuesta (10 minutos) | C22: Shock petrolero (+25%) | D22: Crisis de confianza | E22: Bloqueos (3 semanas) | F22: Crisis bancaria | G22: Freno legislativo
B23: Instrumento que se usa primero | C23: Mecanismo automático de precios (DS 5652) con suavizado trimestral + bono focalizado transitorio a transporte público y productores (registro PEPE) | D23: Comunicación + subasta de divisas con reglas; alza de tasas de títulos BCB; nada de controles ni tipos múltiples | E23: Corredores humanitarios de alimentos/combustible, importación privada autorizada (DS 5644) y diálogo; reprogramar gasto | F23: Liquidez de emergencia (ALE) con garantía, intervención temprana de ASFI y plan de resolución del banco sistémico | G23: Decretos de administración tributaria (sin ley), reprogramar inversión no prioritaria y usar depósitos del SPNF en BCB
B24: Costo que se acepta | C24: Más inflación transitoria y un costo fiscal de 0,15% del PIB | D24: Depreciación y menor crédito por tasas altas | E24: Pérdida de producción del trimestre y 0,1% del PIB en compensaciones | F24: Costo de recapitalización (0,8% PIB) y expansión temporal de la base | G24: Menor inversión pública y caída de depósitos fiscales
B25: Objetivo que se protege prioritariamente | C25: Reservas y saldo primario (no volver a congelar precios) | D25: Reservas (piso de RIN) y ancla nominal | E25: Abastecimiento y precios de alimentos | F25: Depósitos y sistema de pagos | G25: Cero crédito del BCB y saldo primario
B27: Cálculo de impactos sobre el escenario seleccionado
B28: Perfil temporal | D28: 2026 | E28: 2027 | F28: 2028 | G28: 2029
B29: Perfil: Shock petrolero (+25%) | D29: =IF(2026=sel_year,1,IF(2026=sel_year+1,C$13,0)) -> 0 | E29: =IF(2027=sel_year,1,IF(2027=sel_year+1,C$13,0)) -> 1 | F29: =IF(2028=sel_year,1,IF(2028=sel_year+1,C$13,0)) -> 0.6 | G29: =IF(2029=sel_year,1,IF(2029=sel_year+1,C$13,0)) -> 0
B30: Perfil: Crisis de confianza | D30: =IF(2026=sel_year,1,IF(2026=sel_year+1,D$13,0)) -> 0 | E30: =IF(2027=sel_year,1,IF(2027=sel_year+1,D$13,0)) -> 1 | F30: =IF(2028=sel_year,1,IF(2028=sel_year+1,D$13,0)) -> 0.3 | G30: =IF(2029=sel_year,1,IF(2029=sel_year+1,D$13,0)) -> 0
B31: Perfil: Bloqueos (3 semanas) | D31: =IF(2026=sel_year,1,IF(2026=sel_year+1,E$13,0)) -> 0 | E31: =IF(2027=sel_year,1,IF(2027=sel_year+1,E$13,0)) -> 1 | F31: =IF(2028=sel_year,1,IF(2028=sel_year+1,E$13,0)) -> 0 | G31: =IF(2029=sel_year,1,IF(2029=sel_year+1,E$13,0)) -> 0
B32: Perfil: Crisis bancaria | D32: =IF(2026=sel_year,1,IF(2026=sel_year+1,F$13,0)) -> 0 | E32: =IF(2027=sel_year,1,IF(2027=sel_year+1,F$13,0)) -> 1 | F32: =IF(2028=sel_year,1,IF(2028=sel_year+1,F$13,0)) -> 0.5 | G32: =IF(2029=sel_year,1,IF(2029=sel_year+1,F$13,0)) -> 0
B33: Perfil: Freno legislativo | D33: =IF(2026=sel_year,1,IF(2026=sel_year+1,G$13,0)) -> 0 | E33: =IF(2027=sel_year,1,IF(2027=sel_year+1,G$13,0)) -> 1 | F33: =IF(2028=sel_year,1,IF(2028=sel_year+1,G$13,0)) -> 1 | G33: =IF(2029=sel_year,1,IF(2029=sel_year+1,G$13,0)) -> 0
B35: Shock petrolero (+25%) | D35: 2026 | E35: 2027 | F35: 2028 | G35: 2029
B36: Δ crecimiento (pp) | D36: =C$6*D$29*IF(2026=2026,ef26,1)*(1-IF(sel_resp="Sí",C$14,0)) -> 0 | E36: =C$6*E$29*IF(2027=2026,ef26,1)*(1-IF(sel_resp="Sí",C$14,0)) -> -0.18 | F36: =C$6*F$29*IF(2028=2026,ef26,1)*(1-IF(sel_resp="Sí",C$14,0)) -> -0.108 | G36: =C$6*G$29*IF(2029=2026,ef26,1)*(1-IF(sel_resp="Sí",C$14,0)) -> 0
B37: Δ inflación (pp) | D37: =C$16*C$17*100*(1-IF(2026=2026,1,MIN(1,MAX(0,INDEX(Motor!$D$1:$D$600,5+(sel_idx-1)*72+5))/sub_full)))*D$29*IF(2026=2026,ef26,1)*(1-IF(sel_resp="Sí",C$14,0)) -> 0 | E37: =C$16*C$17*100*(1-IF(2027=2026,1,MIN(1,MAX(0,INDEX(Motor!$E$1:$E$600,5+(sel_idx-1)*72+5))/sub_full)))*E$29*IF(2027=2026,ef26,1)*(1-IF(sel_resp="Sí",C$14,0)) -> 0.96 | F37: =C$16*C$17*100*(1-IF(2028=2026,1,MIN(1,MAX(0,INDEX(Motor!$F$1:$F$600,5+(sel_idx-1)*72+5))/sub_full)))*F$29*IF(2028=2026,ef26,1)*(1-IF(sel_resp="Sí",C$14,0)) -> 0.72 | G37: =C$16*C$17*100*(1-IF(2029=2026,1,MIN(1,MAX(0,INDEX(Motor!$G$1:$G$600,5+(sel_idx-1)*72+5))/sub_full)))*G$29*IF(2029=2026,ef26,1)*(1-IF(sel_resp="Sí",C$14,0)) -> 0
B38: Δ saldo primario (pp PIB) | D38: =-C$16*Datos_FMI!$F$26*INDEX(Motor!$D$1:$D$600,5+(sel_idx-1)*72+41)/Datos_FMI!$F$9*100*IF(2026=2026,1,MIN(1,MAX(0,INDEX(Motor!$D$1:$D$600,5+(sel_idx-1)*72+5))/sub_full))*D$29*IF(2026=2026,ef26,1)-IF(sel_resp="Sí",C$15,0)*D$29*IF(2026=2026,ef26,1) -> 0 | E38: =-C$16*Datos_FMI!$G$26*INDEX(Motor!$E$1:$E$600,5+(sel_idx-1)*72+41)/Datos_FMI!$G$9*100*IF(2027=2026,1,MIN(1,MAX(0,INDEX(Motor!$E$1:$E$600,5+(sel_idx-1)*72+5))/sub_full))*E$29*IF(2027=2026,ef26,1)-IF(sel_resp="Sí",C$15,0)*E$29*IF(2027=2026,ef26,1) -> -0.51315694 | F38: =-C$16*Datos_FMI!$H$26*INDEX(Motor!$F$1:$F$600,5+(sel_idx-1)*72+41)/Datos_FMI!$H$9*100*IF(2028=2026,1,MIN(1,MAX(0,INDEX(Motor!$F$1:$F$600,5+(sel_idx-1)*72+5))/sub_full))*F$29*IF(2028=2026,ef26,1)-IF(sel_resp="Sí",C$15,0)*F$29*IF(2028=2026,ef26,1) -> -0.09 | G38: =-C$16*Datos_FMI!$I$26*INDEX(Motor!$G$1:$G$600,5+(sel_idx-1)*72+41)/Datos_FMI!$I$9*100*IF(2029=2026,1,MIN(1,MAX(0,INDEX(Motor!$G$1:$G$600,5+(sel_idx-1)*72+5))/sub_full))*G$29*IF(2029=2026,ef26,1)-IF(sel_resp="Sí",C$15,0)*G$29*IF(2029=2026,ef26,1) -> 0
B39: Δ RIN del año (US$ mn) | D39: =-C$16*Datos_FMI!$F$26*D$29*IF(2026=2026,ef26,1) -> 0 | E39: =-C$16*Datos_FMI!$G$26*E$29*IF(2027=2026,ef26,1) -> -803.75 | F39: =-C$16*Datos_FMI!$H$26*F$29*IF(2028=2026,ef26,1) -> -466.05 | G39: =-C$16*Datos_FMI!$I$26*G$29*IF(2029=2026,ef26,1) -> 0
B40: Δ crédito privado (pp) | D40: =C$10*D$29*IF(2026=2026,ef26,1) -> 0 | E40: =C$10*E$29*IF(2027=2026,ef26,1) -> 0 | F40: =C$10*F$29*IF(2028=2026,ef26,1) -> 0 | G40: =C$10*G$29*IF(2029=2026,ef26,1) -> 0
B41: Δ base monetaria (Bs mn) | D41: =C$11*D$29*IF(2026=2026,ef26,1) -> 0 | E41: =C$11*E$29*IF(2027=2026,ef26,1) -> 0 | F41: =C$11*F$29*IF(2028=2026,ef26,1) -> 0 | G41: =C$11*G$29*IF(2029=2026,ef26,1) -> 0
B42: Δ deuda por recapitalización (pp PIB) | D42: =C$12*D$29*IF(2026=2026,ef26,1) -> 0 | E42: =C$12*E$29*IF(2027=2026,ef26,1) -> 0 | F42: =C$12*F$29*IF(2028=2026,ef26,1) -> 0 | G42: =C$12*G$29*IF(2029=2026,ef26,1) -> 0
B44: Crisis de confianza | D44: 2026 | E44: 2027 | F44: 2028 | G44: 2029
B45: Δ crecimiento (pp) | D45: =D$6*D$30*(1-IF(sel_resp="Sí",D$14,0)) -> 0 | E45: =D$6*E$30*(1-IF(sel_resp="Sí",D$14,0)) -> -0.3 | F45: =D$6*F$30*(1-IF(sel_resp="Sí",D$14,0)) -> -0.09 | G45: =D$6*G$30*(1-IF(sel_resp="Sí",D$14,0)) -> 0
B46: Δ inflación (pp) | D46: =psi*D$19*(1-2/3*INDEX(Palancas!$D$1:$D$400,5+(sel_idx-1)*18+15))*D$30*(1-IF(sel_resp="Sí",D$14,0)) -> 0 | E46: =psi*D$19*(1-2/3*INDEX(Palancas!$D$1:$D$400,5+(sel_idx-1)*18+15))*E$30*(1-IF(sel_resp="Sí",D$14,0)) -> 1.68 | F46: =psi*D$19*(1-2/3*INDEX(Palancas!$D$1:$D$400,5+(sel_idx-1)*18+15))*F$30*(1-IF(sel_resp="Sí",D$14,0)) -> 0.504 | G46: =psi*D$19*(1-2/3*INDEX(Palancas!$D$1:$D$400,5+(sel_idx-1)*18+15))*G$30*(1-IF(sel_resp="Sí",D$14,0)) -> 0
B47: Δ saldo primario (pp PIB) | D47: =D$8*D$30-IF(sel_resp="Sí",D$15,0)*D$30 -> 0 | E47: =D$8*E$30-IF(sel_resp="Sí",D$15,0)*E$30 -> 0 | F47: =D$8*F$30-IF(sel_resp="Sí",D$15,0)*F$30 -> 0 | G47: =D$8*G$30-IF(sel_resp="Sí",D$15,0)*G$30 -> 0
B48: Δ RIN del año (US$ mn) | D48: =-D$18*(0.2+0.6*INDEX(Palancas!$D$1:$D$400,5+(sel_idx-1)*18+15))*D$30 -> 0 | E48: =-D$18*(0.2+0.6*INDEX(Palancas!$D$1:$D$400,5+(sel_idx-1)*18+15))*E$30 -> -400 | F48: =-D$18*(0.2+0.6*INDEX(Palancas!$D$1:$D$400,5+(sel_idx-1)*18+15))*F$30 -> -120 | G48: =-D$18*(0.2+0.6*INDEX(Palancas!$D$1:$D$400,5+(sel_idx-1)*18+15))*G$30 -> 0
...

Sheet Seleccionado
B2: Escenario seleccionado (+ shock) frente a la Base FMI
B3: Alimenta el Dashboard. Cambie la selección en el Dashboard.
B4: ="Escenario: "&sel_scen&" · Shock: "&sel_shock&IF(shock_idx>0," ("&sel_year&", respuesta: "&sel_resp&")","") -> Escenario: E6 Alternativo integrado · Shock: Ninguno
B6: Indicador | C6: FMI 2026 | D6: FMI 2027 | E6: FMI 2028 | F6: FMI 2029 | G6: Alt. 2026 | H6: Alt. 2027 | I6: Alt. 2028 | J6: Alt. 2029
B7: Crecimiento PIB real (%) | C7: =Motor!$D$29 -> -3 | D7: =Motor!$E$29 -> -1.5 | E7: =Motor!$F$29 -> 0.5 | F7: =Motor!$G$29 -> 2.5 | G7: =INDEX(Motor!$D$1:$D$600,5+(sel_idx-1)*72+24)+Shocks!D$81 -> -2.97175 | H7: =INDEX(Motor!$E$1:$E$600,5+(sel_idx-1)*72+24)+Shocks!E$81 -> -0.808 | I7: =INDEX(Motor!$F$1:$F$600,5+(sel_idx-1)*72+24)+Shocks!F$81 -> 1.059 | J7: =INDEX(Motor!$G$1:$G$600,5+(sel_idx-1)*72+24)+Shocks!G$81 -> 2.861
B8: Inflación promedio (%) | C8: =Motor!$D$48 -> 12.7 | D8: =Motor!$E$48 -> 15.8 | E8: =Motor!$F$48 -> 8.2 | F8: =Motor!$G$48 -> 7.3 | G8: =INDEX(Motor!$D$1:$D$600,5+(sel_idx-1)*72+43)+Shocks!D$82 -> 12.710562 | H8: =INDEX(Motor!$E$1:$E$600,5+(sel_idx-1)*72+43)+Shocks!E$82 -> 15.8265 | I8: =INDEX(Motor!$F$1:$F$600,5+(sel_idx-1)*72+43)+Shocks!F$82 -> 8.31375 | J8: =INDEX(Motor!$G$1:$G$600,5+(sel_idx-1)*72+43)+Shocks!G$82 -> 7.32725
B9: Inflación fin de período (%) | C9: =Motor!$D$49 -> 14.2 | D9: =Motor!$E$49 -> 10.7 | E9: =Motor!$F$49 -> 8.7 | F9: =Motor!$G$49 -> 6.2 | G9: =INDEX(Motor!$D$1:$D$600,5+(sel_idx-1)*72+44)+Shocks!D$82 -> 14.210562 | H9: =INDEX(Motor!$E$1:$E$600,5+(sel_idx-1)*72+44)+Shocks!E$82 -> 10.7265 | I9: =INDEX(Motor!$F$1:$F$600,5+(sel_idx-1)*72+44)+Shocks!F$82 -> 8.81375 | J9: =INDEX(Motor!$G$1:$G$600,5+(sel_idx-1)*72+44)+Shocks!G$82 -> 6.22725
B10: Saldo primario (% PIB) | C10: =Motor!$D$33 -> -6.5 | D10: =Motor!$E$33 -> -3 | E10: =Motor!$F$33 -> -0.3 | F10: =Motor!$G$33 -> 0.6 | G10: =INDEX(Motor!$D$1:$D$600,5+(sel_idx-1)*72+28)+Shocks!D$83+auto*Shocks!D$81 -> -6.47685 | H10: =INDEX(Motor!$E$1:$E$600,5+(sel_idx-1)*72+28)+Shocks!E$83+auto*Shocks!E$81 -> -2.8866 | I10: =INDEX(Motor!$F$1:$F$600,5+(sel_idx-1)*72+28)+Shocks!F$83+auto*Shocks!F$81 -> 0.4518 | J10: =INDEX(Motor!$G$1:$G$600,5+(sel_idx-1)*72+28)+Shocks!G$83+auto*Shocks!G$81 -> 1.6622
B11: Saldo primario (Bs mn) | C11: =Motor!$D$34 -> -32869 | D11: =Motor!$E$34 -> -17466 | E11: =Motor!$F$34 -> -1861.113 | F11: =Motor!$G$34 -> 4067.604 | G11: =INDEX(Motor!$D$1:$D$600,5+(sel_idx-1)*72+29)+(Shocks!D$83+auto*Shocks!D$81)/100*Datos_FMI!$F$9 -> -32751.77 | H11: =INDEX(Motor!$E$1:$E$600,5+(sel_idx-1)*72+29)+(Shocks!E$83+auto*Shocks!E$81)/100*Datos_FMI!$G$9 -> -16810.209 | I11: =INDEX(Motor!$F$1:$F$600,5+(sel_idx-1)*72+29)+(Shocks!F$83+auto*Shocks!F$81)/100*Datos_FMI!$H$9 -> 2802.8362 | J11: =INDEX(Motor!$G$1:$G$600,5+(sel_idx-1)*72+29)+(Shocks!G$83+auto*Shocks!G$81)/100*Datos_FMI!$I$9 -> 11268.619
B12: Saldo global (% PIB) | C12: =Motor!$D$37 -> -9.2 | D12: =Motor!$E$37 -> -6.7 | E12: =Motor!$F$37 -> -4 | F12: =Motor!$G$37 -> -3.2 | G12: =INDEX(Motor!$D$1:$D$600,5+(sel_idx-1)*72+32)+Shocks!D$83+auto*Shocks!D$81 -> -9.17685 | H12: =INDEX(Motor!$E$1:$E$600,5+(sel_idx-1)*72+32)+Shocks!E$83+auto*Shocks!E$81 -> -6.5852824 | I12: =INDEX(Motor!$F$1:$F$600,5+(sel_idx-1)*72+32)+Shocks!F$83+auto*Shocks!F$81 -> -3.2219738 | J12: =INDEX(Motor!$G$1:$G$600,5+(sel_idx-1)*72+32)+Shocks!G$83+auto*Shocks!G$81 -> -2.043951
B13: Deuda SPNF (% PIB) | C13: =Motor!$D$55 -> 100.47769 | D13: =Motor!$E$55 -> 95.361223 | E13: =Motor!$F$55 -> 93.185529 | F13: =Motor!$G$55 -> 89.203374 | G13: =INDEX(Motor!$D$1:$D$600,5+(sel_idx-1)*72+50)-(Shocks!D$83)-auto*(Shocks!D$81)+(Shocks!D$87) -> 100.41557 | H13: =INDEX(Motor!$E$1:$E$600,5+(sel_idx-1)*72+50)-(Shocks!D$83+Shocks!E$83)-auto*(Shocks!D$81+Shocks!E$81)+(Shocks!D$87+Shocks!E$87) -> 94.214638 | I13: =INDEX(Motor!$F$1:$F$600,5+(sel_idx-1)*72+50)-(Shocks!D$83+Shocks!E$83+Shocks!F$83)-auto*(Shocks!D$81+Shocks!E$81+Shocks!F$81)+(Shocks!D$87+Shocks!E$87+Shocks!F$87) -> 90.314434 | J13: =INDEX(Motor!$G$1:$G$600,5+(sel_idx-1)*72+50)-(Shocks!D$83+Shocks!E$83+Shocks!F$83+Shocks!G$83)-auto*(Shocks!D$81+Shocks!E$81+Shocks!F$81+Shocks!G$81)+(Shocks!D$87+Shocks!E$87+Shocks!F$87+Shocks!G$87) -> 84.846923
B14: RIN del programa (US$ mn) | C14: =Motor!$D$59 -> -581 | D14: =Motor!$E$59 -> 744 | E14: =Motor!$F$59 -> 1304 | F14: =Motor!$G$59 -> 1878 | G14: =INDEX(Motor!$D$1:$D$600,5+(sel_idx-1)*72+54)+(Shocks!D$84) -> -586.29349 | H14: =INDEX(Motor!$E$1:$E$600,5+(sel_idx-1)*72+54)+(Shocks!D$84+Shocks!E$84) -> 703.74912 | I14: =INDEX(Motor!$F$1:$F$600,5+(sel_idx-1)*72+54)+(Shocks!D$84+Shocks!E$84+Shocks!F$84) -> 1302.8827 | J14: =INDEX(Motor!$G$1:$G$600,5+(sel_idx-1)*72+54)+(Shocks!D$84+Shocks!E$84+Shocks!F$84+Shocks!G$84) -> 1800.8561
B15: RIB programa / ARA (%) | C15: =Motor!$D$61 -> 53.4 | D15: =Motor!$E$61 -> 86.1 | E15: =Motor!$F$61 -> 100.1 | F15: =Motor!$G$61 -> 112.3 | G15: =INDEX(Motor!$D$1:$D$600,5+(sel_idx-1)*72+56)*(1+(Shocks!D$84)/INDEX(Motor!$D$1:$D$600,5+(sel_idx-1)*72+55)) -> 53.284999 | H15: =INDEX(Motor!$E$1:$E$600,5+(sel_idx-1)*72+56)*(1+(Shocks!D$84+Shocks!E$84)/INDEX(Motor!$E$1:$E$600,5+(sel_idx-1)*72+55)) -> 85.229683 | I15: =INDEX(Motor!$F$1:$F$600,5+(sel_idx-1)*72+56)*(1+(Shocks!D$84+Shocks!E$84+Shocks!F$84)/INDEX(Motor!$F$1:$F$600,5+(sel_idx-1)*72+55)) -> 100.07615 | J15: =INDEX(Motor!$G$1:$G$600,5+(sel_idx-1)*72+56)*(1+(Shocks!D$84+Shocks!E$84+Shocks!F$84+Shocks!G$84)/INDEX(Motor!$G$1:$G$600,5+(sel_idx-1)*72+55)) -> 110.73256
B16: Crédito privado (variación %) | C16: =Motor!$D$63 -> 4 | D16: =Motor!$E$63 -> 7.3 | E16: =Motor!$F$63 -> 7.3 | F16: =Motor!$G$63 -> 9.5 | G16: =INDEX(Motor!$D$1:$D$600,5+(sel_idx-1)*72+58)+Shocks!D$85 -> 4.25 | H16: =INDEX(Motor!$E$1:$E$600,5+(sel_idx-1)*72+58)+Shocks!E$85 -> 10.55 | I16: =INDEX(Motor!$F$1:$F$600,5+(sel_idx-1)*72+58)+Shocks!F$85 -> 10.3 | J16: =INDEX(Motor!$G$1:$G$600,5+(sel_idx-1)*72+58)+Shocks!G$85 -> 11.5
B17: Base monetaria (Bs mn) | C17: =Motor!$D$66 -> 133900 | D17: =Motor!$E$66 -> 148333 | E17: =Motor!$F$66 -> 161304 | F17: =Motor!$G$66 -> 177013 | G17: =INDEX(Motor!$D$1:$D$600,5+(sel_idx-1)*72+61)+Shocks!D$86 -> 133900 | H17: =INDEX(Motor!$E$1:$E$600,5+(sel_idx-1)*72+61)+Shocks!E$86 -> 149074.67 | I17: =INDEX(Motor!$F$1:$F$600,5+(sel_idx-1)*72+61)+Shocks!F$86 -> 162110.52 | J17: =INDEX(Motor!$G$1:$G$600,5+(sel_idx-1)*72+61)+Shocks!G$86 -> 177898.07
B18: Crédito BCB requerido (Bs mn) | C18: =Motor!$D$42 -> 0 | D18: =Motor!$E$42 -> 0 | E18: =Motor!$F$42 -> 0 | F18: =Motor!$G$42 -> 0 | G18: =INDEX(Motor!$D$1:$D$600,5+(sel_idx-1)*72+37) -> 0 | H18: =INDEX(Motor!$E$1:$E$600,5+(sel_idx-1)*72+37) -> 0 | I18: =INDEX(Motor!$F$1:$F$600,5+(sel_idx-1)*72+37) -> 0 | J18: =INDEX(Motor!$G$1:$G$600,5+(sel_idx-1)*72+37) -> 0
B19: Asistencia social (Bs mn) | C19: =Motor!$D$68 -> 10890 | D19: =Motor!$E$68 -> 12722.578 | E19: =Motor!$F$68 -> 8064.823 | F19: =Motor!$G$68 -> 8813.142 | G19: =INDEX(Motor!$D$1:$D$600,5+(sel_idx-1)*72+63) -> 10890 | H19: =INDEX(Motor!$E$1:$E$600,5+(sel_idx-1)*72+63) -> 14168.326 | I19: =INDEX(Motor!$F$1:$F$600,5+(sel_idx-1)*72+63) -> 9305.565 | J19: =INDEX(Motor!$G$1:$G$600,5+(sel_idx-1)*72+63) -> 9830.043
B20: Δ Empleo vs FMI (miles) | C20: =Motor!$D$69 -> 0 | D20: =Motor!$E$69 -> 0 | E20: =Motor!$F$69 -> 0 | F20: =Motor!$G$69 -> 0 | G20: =INDEX(Motor!$D$1:$D$600,5+(sel_idx-1)*72+64)+emp_el*(Shocks!D$81)/100*pea -> 0.904 | H20: =INDEX(Motor!$E$1:$E$600,5+(sel_idx-1)*72+64)+emp_el*(Shocks!D$81+Shocks!E$81)/100*pea -> 23.048 | I20: =INDEX(Motor!$F$1:$F$600,5+(sel_idx-1)*72+64)+emp_el*(Shocks!D$81+Shocks!E$81+Shocks!F$81)/100*pea -> 40.936 | J20: =INDEX(Motor!$G$1:$G$600,5+(sel_idx-1)*72+64)+emp_el*(Shocks!D$81+Shocks!E$81+Shocks!F$81+Shocks!G$81)/100*pea -> 52.488
B21: Δ Pobreza vs FMI (pp) | C21: =Motor!$D$70 -> 0 | D21: =Motor!$E$70 -> 0 | E21: =Motor!$F$70 -> 0 | F21: =Motor!$G$70 -> 0 | G21: =INDEX(Motor!$D$1:$D$600,5+(sel_idx-1)*72+65)-pov_g*(Shocks!D$81)+pov_pi*Shocks!D$82 -> -0.018190625 | H21: =INDEX(Motor!$E$1:$E$600,5+(sel_idx-1)*72+65)-pov_g*(Shocks!D$81+Shocks!E$81)+pov_pi*Shocks!E$82 -> -1.0602 | I21: =INDEX(Motor!$F$1:$F$600,5+(sel_idx-1)*72+65)-pov_g*(Shocks!D$81+Shocks!E$81+Shocks!F$81)+pov_pi*Shocks!F$82 -> -1.2784125 | J21: =INDEX(Motor!$G$1:$G$600,5+(sel_idx-1)*72+65)-pov_g*(Shocks!D$81+Shocks!E$81+Shocks!F$81+Shocks!G$81)+pov_pi*Shocks!G$82 -> -1.4440875
B22: Δ Gini vs FMI (pts) | C22: =Motor!$D$71 -> 0 | D22: =Motor!$E$71 -> 0 | E22: =Motor!$F$71 -> 0 | F22: =Motor!$G$71 -> 0 | G22: =INDEX(Motor!$D$1:$D$600,5+(sel_idx-1)*72+66) -> 0 | H22: =INDEX(Motor!$E$1:$E$600,5+(sel_idx-1)*72+66) -> -0.145 | I22: =INDEX(Motor!$F$1:$F$600,5+(sel_idx-1)*72+66) -> -0.17 | J22: =INDEX(Motor!$G$1:$G$600,5+(sel_idx-1)*72+66) -> -0.18
B24: Metas a dic-2026 (seleccionado + shock) | C24: Valor | D24: Meta | E24: Holgura | F24: Estado
B25: Saldo primario (Bs mn) | C25: =G11 -> -32751.77 | D25: =meta_pb -> -33000 | E25: =C25-D25 -> 248.22952 | F25: =IF(ROUND(E25,0)>=0,"Cumple","No cumple") -> Cumple
B26: Variación RIN (US$ mn) | C26: =G14-Datos_FMI!$E$31 -> 2403.7065 | D26: =meta_nir -> 2400 | E26: =C26-D26 -> 3.706515 | F26: =IF(ROUND(E26,0)>=0,"Cumple","No cumple") -> Cumple
B27: Crédito BCB al sector público (Bs mn) | C27: =G18 -> 0 | D27: =meta_bcb -> 0 | E27: =D27-C27 -> 0 | F27: =IF(ROUND(E27,0)>=0,"Cumple","No cumple") -> Cumple
B28: Asistencia social (Bs mn) | C28: =G19 -> 10890 | D28: =meta_soc -> 9300 | E28: =C28-D28 -> 1590 | F28: =IF(ROUND(E28,0)>=0,"Cumple","No cumple") -> Cumple
B29: Base monetaria (Bs mn) | C29: =G17 -> 133900 | D29: =meta_bm -> 133900 | E29: =D29-C29 -> 0 | F29: =IF(ROUND(E29,0)>=0,"Cumple","No cumple") -> Cumple

Sheet Evaluacion
B2: Evaluación de escenarios: metas 2026 e índice de eficiencia
B3: Sin shocks. Índice 0–100: normalización mín–máx entre escenarios, ponderada (pesos editables).
B5: Indicador | C5: Base FMI | D5: E1 Fiscal gradual | E5: E2 Monetaria-crédito | F5: E3 Banda cambiaria | G5: E4 Tributaria progresiva | H5: E5 Protección social | I5: E6 Alternativo integrado | J5: Meta / peso
B6: Saldo primario 2026 (Bs mn) | C6: =Motor!$D$34 -> -32869 | D6: =Motor!$D$106 -> -33413.37 | E6: =Motor!$D$178 -> -32838.617 | F6: =Motor!$D$250 -> -32884.192 | G6: =Motor!$D$322 -> -32695.308 | H6: =Motor!$D$394 -> -32858.872 | I6: =Motor!$D$466 -> -32751.77 | J6: =meta_pb -> -33000
B7: Variación RIN 2026 (US$ mn) | C7: =Motor!$D$59-Datos_FMI!$E$31 -> 2409 | D7: =Motor!$D$131-Datos_FMI!$E$31 -> 2492.6042 | E7: =Motor!$D$203-Datos_FMI!$E$31 -> 2403.3786 | F7: =Motor!$D$275-Datos_FMI!$E$31 -> 2261.8107 | G7: =Motor!$D$347-Datos_FMI!$E$31 -> 2409.6558 | H7: =Motor!$D$419-Datos_FMI!$E$31 -> 2407.1262 | I7: =Motor!$D$491-Datos_FMI!$E$31 -> 2403.7065 | J7: =meta_nir -> 2400
